Workbook

Sheet Assumptions
A1: Baburra Product Model — Assumptions
A3: 1. External API Unit Costs
A4: Item | B4: Unit Cost | C4: Unit | D4: Notes / Source
A5: Gemini 2.5 Flash-Lite — Input | B5: 0.0001 | C5: per 1K tokens | D5: Current model (AI_SENTIMENT_MODEL). $0.10/1M input
A6: Gemini 2.5 Flash-Lite — Output | B6: 0.0004 | C6: per 1K tokens | D6: $0.40/1M output
A7: Gemini 2.5 Flash — Input (upgrade path) | B7: 0.0003 | C7: per 1K tokens | D7: $0.30/1M input. Zero migration effort.
A8: Gemini 2.5 Flash — Output (upgrade path) | B8: 0.0025 | C8: per 1K tokens | D8: $2.50/1M output
A9: Deepgram Nova-3 — Pre-recorded | B9: 0.0043 | C9: per minute | D9: Batch transcription (video→text)
A10: Deepgram Nova-3 — Streaming | B10: 0.0077 | C10: per minute | D10: Not needed for Baburra use case
A11: Apify TikTok Scraper | B11: 0.0003 | C11: per post | D11: $0.30/1K posts (apidojo actor)
A12: Apify Facebook Scraper | B12: 0.001 | C12: per post | D12: Estimate — varies by actor
A13: Apify Compute Unit | B13: 0.25 | C13: per CU | D13: 1 CU = 1GB RAM × 1 hour
A14: YouTube Data API | B14: 0 | C14: per call | D14: Free quota: 10K units/day. Transcript via youtube-transcript-plus: free
A15: Twitter/X oEmbed | B15: 0 | C15: per call | D15: Free public endpoint
A16: Podcast RSS | B16: 0 | C16: per feed | D16: Open standard, zero cost
A18: 2. Infrastructure Fixed Costs (Monthly)
A19: Item | B19: Cost/mo | C19: Unit | D19: Notes
A20: Vercel Hobby (current) | B20: 0 | C20: — | D20: Free. crons removed to fix deploy. Consider Pro ($20/mo) for cron jobs
A21: Vercel Pro (future) | B21: 20 | C21: — | D21: Needed for scheduled seed scraping (cron)
A22: Supabase Pro | B22: 25 | C22: — | D22: $25 base + $10 compute credit. 8GB DB, 100K MAU
A23: Supabase Compute (Micro) | B23: 0 | C23: — | D23: Covered by $10 compute credit on Pro
A24: Domain (annual ÷ 12) | B24: 1 | C24: — | D24: ~$12/yr estimate
A25: Deepgram $200 free credit | B25: 0 | C25: — | D25: Covers ~46,500 min of batch transcription. Lasts months at seed scale.
A26: Total Infra (Phase 1: Hobby+Supa Pro) | B26: =B20+B22+B24 -> 26 | D26: Vercel Hobby + Supabase Pro + Domain
A27: Total Infra (Phase 2: Vercel Pro+Supa Pro) | B27: =B21+B22+B24 -> 46
A29: 3. Content Processing Assumptions (per scrape)
A30: Content Type | B30: Avg Value | C30: Unit | D30: Notes / Assumption
A31: YouTube long-form video | B31: 15 | C31: min avg duration | D31: A: Typical TW stock KOL video 10-20 min
A32: YouTube Shorts | B32: 0.5 | C32: min avg duration | D32: A: ≤60s by definition
A33: Podcast episode | B33: 45 | C33: min avg duration | D33: A: Typical investment podcast 30-60 min
A34: TikTok video | B34: 0.5 | C34: min avg duration | D34: A: Short-form ≤60s
A35: Twitter/X post | B35: 0.15 | C35: K tokens (input) | D35: A: ~100 words avg tweet → ~150 tokens
A36: Facebook post | B36: 0.3 | C36: K tokens (input) | D36: A: Longer than tweets, ~200 words
A37: Gemini prompt overhead | B37: 1.5 | C37: K tokens (input) | D37: A: System prompt + schema per call
A38: Gemini output per post | B38: 0.5 | C38: K tokens (output) | D38: A: Structured JSON response ~350 tokens
A39: Posts per KOL scrape (YouTube) | B39: 10 | C39: posts | D39: A: Last 10 videos per profile scrape
A40: Posts per KOL scrape (Twitter) | B40: 20 | C40: posts | D40: A: Last 20 tweets per profile scrape
A41: Posts per KOL scrape (Podcast) | B41: 5 | C41: episodes | D41: A: Last 5 episodes per feed scrape
A42: Posts per KOL scrape (TikTok) | B42: 15 | C42: posts | D42: A: Last 15 videos per profile scrape
... A45: Keyword pre-filter pass rate (short-form) | B45: 0.4 | C45: ratio | D45: A: 40% of short-form videos pass keyword filter before transcription
...

Sheet Cost Model (12mo)
A1: Baburra — Monthly Cost Projection (12 Months)
A3: Month → | B3: M1 | C3: M2 | D3: M3 | E3: M4 | F3: M5 | G3: M6 | H3: M7 | I3: M8 | J3: M9 | K3: M10 | L3: M11 | M3: M12
A4: Seed Scraping Costs (Platform-funded)
A5: Seed KOLs tracked | B5: 30 | C5: 30 | D5: 30 | E5: 40 | F5: 40 | G5: 40 | H5: 50 | I5: 50 | J5: 50 | K5: 60 | L5: 60 | M5: 60
A6: Scrapes/month (total) | B6: =B5*2 -> 60 | C6: =C5*2 -> 60 | D6: =D5*2 -> 60 | E6: =E5*2 -> 80 | F6: =F5*2 -> 80 | G6: =G5*2 -> 80 | H6: =H5*2 -> 100 | I6: =I5*2 -> 100 | ... M6: =M5*2 -> 120
A7: New posts processed/month | B7: =B6*3 -> 180 | C7: =C6*3 -> 180 | D7: =D6*3 -> 180 | E7: =E6*3 -> 240 | F7: =F6*3 -> 240 | G7: =G6*3 -> 240 | H7: =H6*3 -> 300 | I7: =I6*3 -> 300 | ... M7: =M6*3 -> 360
A8: YouTube video minutes transcribed | B8: =B7*0.5*15 -> 1350 | C8: =C7*0.5*15 -> 1350 | D8: =D7*0.5*15 -> 1350 | E8: =E7*0.5*15 -> 1800 | F8: =F7*0.5*15 -> 1800 | G8: =G7*0.5*15 -> 1800 | H8: =H7*0.5*15 -> 2250 | I8: =I7*0.5*15 -> 2250 | ... M8: =M7*0.5*15 -> 2700
A9: Podcast minutes transcribed | B9: =B7*0.17*45 -> 1377 | C9: =C7*0.17*45 -> 1377 | D9: =D7*0.17*45 -> 1377 | E9: =E7*0.17*45 -> 1836 | F9: =F7*0.17*45 -> 1836 | G9: =G7*0.17*45 -> 1836 | H9: =H7*0.17*45 -> 2295 | I9: =I7*0.17*45 -> 2295 | ... M9: =M7*0.17*45 -> 2754
A10: Deepgram cost | B10: =(B8+B9)*0.0043 -> 11.7261 | C10: =(C8+C9)*0.0043 -> 11.7261 | D10: =(D8+D9)*0.0043 -> 11.7261 | E10: =(E8+E9)*0.0043 -> 15.6348 | F10: =(F8+F9)*0.0043 -> 15.6348 | G10: =(G8+G9)*0.0043 -> 15.6348 | H10: =(H8+H9)*0.0043 -> 19.5435 | I10: =(I8+I9)*0.0043 -> 19.5435 | ... M10: =(M8+M9)*0.0043 -> 23.4522
A11: Gemini input tokens (K) | B11: =B7*3.5 -> 630 | C11: =C7*3.5 -> 630 | D11: =D7*3.5 -> 630 | E11: =E7*3.5 -> 840 | F11: =F7*3.5 -> 840 | G11: =G7*3.5 -> 840 | H11: =H7*3.5 -> 1050 | I11: =I7*3.5 -> 1050 | ... M11: =M7*3.5 -> 1260
A12: Gemini output tokens (K) | B12: =B7*0.5 -> 90 | C12: =C7*0.5 -> 90 | D12: =D7*0.5 -> 90 | E12: =E7*0.5 -> 120 | F12: =F7*0.5 -> 120 | G12: =G7*0.5 -> 120 | H12: =H7*0.5 -> 150 | I12: =I7*0.5 -> 150 | ... M12: =M7*0.5 -> 180
A13: Gemini cost | B13: =B11*0.0001+B12*0.0004 -> 0.099 | C13: =C11*0.0001+C12*0.0004 -> 0.099 | D13: =D11*0.0001+D12*0.0004 -> 0.099 | E13: =E11*0.0001+E12*0.0004 -> 0.132 | F13: =F11*0.0001+F12*0.0004 -> 0.132 | G13: =G11*0.0001+G12*0.0004 -> 0.132 | H13: =H11*0.0001+H12*0.0004 -> 0.165 | I13: =I11*0.0001+I12*0.0004 -> 0.165 | ... M13: =M11*0.0001+M12*0.0004 -> 0.198
A14: Total seed scraping cost/mo | B14: =B10+B13 -> 11.8251 | C14: =C10+C13 -> 11.8251 | D14: =D10+D13 -> 11.8251 | E14: =E10+E13 -> 15.7668 | F14: =F10+F13 -> 15.7668 | G14: =G10+G13 -> 15.7668 | H14: =H10+H13 -> 19.7085 | I14: =I10+I13 -> 19.7085 | ... M14: =M10+M13 -> 23.6502
A16: Infrastructure Costs
A17: Vercel | B17: 0 | C17: 0 | D17: 0 | E17: 0 | F17: 20 | G17: 20 | H17: 20 | I17: 20 | J17: 20 | K17: 20 | L17: 20 | M17: 20
A18: Supabase Pro | B18: 25 | C18: 25 | D18: 25 | E18: 25 | F18: 25 | G18: 25 | H18: 25 | I18: 25 | J18: 25 | K18: 25 | L18: 25 | M18: 25
A19: Domain | B19: 1 | C19: 1 | D19: 1 | E19: 1 | F19: 1 | G19: 1 | H19: 1 | I19: 1 | J19: 1 | K19: 1 | L19: 1 | M19: 1
A20: Total Infrastructure | B20: =B17+B18+B19 -> 26 | C20: =C17+C18+C19 -> 26 | D20: =D17+D18+D19 -> 26 | E20: =E17+E18+E19 -> 26 | F20: =F17+F18+F19 -> 46 | G20: =G17+G18+G19 -> 46 | H20: =H17+H18+H19 -> 46 | I20: =I17+I18+I19 -> 46 | ... M20: =M17+M18+M19 -> 46
A22: Total Monthly Costs (Platform)
A23: TOTAL COST / MONTH | B23: =B14+B20 -> 37.8251 | C23: =C14+C20 -> 37.8251 | D23: =D14+D20 -> 37.8251 | E23: =E14+E20 -> 41.7668 | F23: =F14+F20 -> 61.7668 | G23: =G14+G20 -> 61.7668 | H23: =H14+H20 -> 65.7085 | I23: =I14+I20 -> 65.7085 | ... M23: =M14+M20 -> 69.6502

Sheet Revenue Model (12mo)
A1: Baburra — Monthly Revenue Projection (12 Months)
A3: Month → | B3: M1 | C3: M2 | D3: M3 | E3: M4 | F3: M5 | G3: M6 | H3: M7 | I3: M8 | J3: M9 | K3: M10 | L3: M11 | M3: M12
A4: User Growth
A5: Free users (cumulative) | B5: 10 | C5: 20 | D5: 30 | E5: 40 | F5: 55 | G5: 70 | H5: 85 | I5: 100 | J5: 120 | K5: 140 | L5: 165 | M5: 195
A6: Pro subscribers | B6: 2 | C6: 3 | D6: 5 | E6: 7 | F6: 9 | G6: 12 | H6: 15 | I6: 18 | J6: 22 | K6: 27 | L6: 33 | M6: 40
A7: Max subscribers | B7: 0 | C7: 0 | D7: 0 | E7: 1 | F7: 1 | G7: 2 | H7: 2 | I7: 3 | J7: 4 | K7: 5 | L7: 6 | M7: 8
A8: Total paying users | B8: =B6+B7 -> 2 | C8: =C6+C7 -> 3 | D8: =D6+D7 -> 5 | E8: =E6+E7 -> 8 | F8: =F6+F7 -> 10 | G8: =G6+G7 -> 14 | H8: =H6+H7 -> 17 | I8: =I6+I7 -> 21 | ... M8: =M6+M7 -> 48
A9: Total users (all tiers) | B9: =B5+B8 -> 12 | C9: =C5+C8 -> 23 | D9: =D5+D8 -> 35 | E9: =E5+E8 -> 48 | F9: =F5+F8 -> 65 | G9: =G5+G8 -> 84 | H9: =H5+H8 -> 102 | I9: =I5+I8 -> 121 | ... M9: =M5+M8 -> 243
A11: Subscription Revenue
A12: Pro MRR | B12: =B6*9.99 -> 19.98 | C12: =C6*9.99 -> 29.97 | D12: =D6*9.99 -> 49.95 | E12: =E6*9.99 -> 69.93 | F12: =F6*9.99 -> 89.91 | G12: =G6*9.99 -> 119.88 | H12: =H6*9.99 -> 149.85 | I12: =I6*9.99 -> 179.82 | ... M12: =M6*9.99 -> 399.6
A13: Max MRR | B13: =B7*24.99 -> 0 | C13: =C7*24.99 -> 0 | D13: =D7*24.99 -> 0 | E13: =E7*24.99 -> 24.99 | F13: =F7*24.99 -> 24.99 | G13: =G7*24.99 -> 49.98 | H13: =H7*24.99 -> 49.98 | I13: =I7*24.99 -> 74.97 | ... M13: =M7*24.99 -> 199.92
A14: Credit pack revenue (est) | B14: =B5*0.1*2.5+B6*0.05*2.5 -> 2.75 | C14: =C5*0.1*2.5+C6*0.05*2.5 -> 5.375 | D14: =D5*0.1*2.5+D6*0.05*2.5 -> 8.125 | E14: =E5*0.1*2.5+E6*0.05*2.5 -> 10.875 | F14: =F5*0.1*2.5+F6*0.05*2.5 -> 14.875 | G14: =G5*0.1*2.5+G6*0.05*2.5 -> 19 | H14: =H5*0.1*2.5+H6*0.05*2.5 -> 23.125 | I14: =I5*0.1*2.5+I6*0.05*2.5 -> 27.25 | ... M14: =M5*0.1*2.5+M6*0.05*2.5 -> 53.75
A15: Gross Revenue | B15: =B12+B13+B14 -> 22.73 | C15: =C12+C13+C14 -> 35.345 | D15: =D12+D13+D14 -> 58.075 | E15: =E12+E13+E14 -> 105.795 | F15: =F12+F13+F14 -> 129.775 | G15: =G12+G13+G14 -> 188.86 | H15: =H12+H13+H14 -> 222.955 | I15: =I12+I13+I14 -> 282.04 | ... M15: =M12+M13+M14 -> 653.27
A16: Stripe fees | B16: =B15*0.029+B8*0.3 -> 1.25917 | C16: =C15*0.029+C8*0.3 -> 1.925005 | D16: =D15*0.029+D8*0.3 -> 3.184175 | E16: =E15*0.029+E8*0.3 -> 5.468055 | F16: =F15*0.029+F8*0.3 -> 6.763475 | G16: =G15*0.029+G8*0.3 -> 9.67694 | H16: =H15*0.029+H8*0.3 -> 11.565695 | I16: =I15*0.029+I8*0.3 -> 14.47916 | ... M16: =M15*0.029+M8*0.3 -> 33.34483
A17: Net Revenue | B17: =B15-B16 -> 21.47083 | C17: =C15-C16 -> 33.419995 | D17: =D15-D16 -> 54.890825 | E17: =E15-E16 -> 100.32694 | F17: =F15-F16 -> 123.01153 | G17: =G15-G16 -> 179.18306 | H17: =H15-H16 -> 211.38931 | I17: =I15-I16 -> 267.56084 | ... M17: =M15-M16 -> 619.92517
A19: Unit Economics Snapshot
A20: ARPU (paying) | B20: =IF(B8>0,B17/B8,0) -> 10.735415 | C20: =IF(C8>0,C17/C8,0) -> 11.139998 | D20: =IF(D8>0,D17/D8,0) -> 10.978165 | E20: =IF(E8>0,E17/E8,0) -> 12.540868 | F20: =IF(F8>0,F17/F8,0) -> 12.301153 | G20: =IF(G8>0,G17/G8,0) -> 12.79879 | H20: =IF(H8>0,H17/H8,0) -> 12.434665 | I20: =IF(I8>0,I17/I8,0) -> 12.740992 | ... M20: =IF(M8>0,M17/M8,0) -> 12.915108
A21: Total platform cost (from Cost sheet) | B21: ='Cost Model (12mo)'!B23 -> 37.8251 | C21: ='Cost Model (12mo)'!C23 -> 37.8251 | D21: ='Cost Model (12mo)'!D23 -> 37.8251 | E21: ='Cost Model (12mo)'!E23 -> 41.7668 | F21: ='Cost Model (12mo)'!F23 -> 61.7668 | G21: ='Cost Model (12mo)'!G23 -> 61.7668 | H21: ='Cost Model (12mo)'!H23 -> 65.7085 | I21: ='Cost Model (12mo)'!I23 -> 65.7085 | ... M21: ='Cost Model (12mo)'!M23 -> 69.6502
A22: Cost per paying user | B22: =IF(B8>0,B21/B8,0) -> 18.91255 | C22: =IF(C8>0,C21/C8,0) -> 12.608367 | D22: =IF(D8>0,D21/D8,0) -> 7.56502 | E22: =IF(E8>0,E21/E8,0) -> 5.22085 | F22: =IF(F8>0,F21/F8,0) -> 6.17668 | G22: =IF(G8>0,G21/G8,0) -> 4.4119143 | H22: =IF(H8>0,H21/H8,0) -> 3.8652059 | I22: =IF(I8>0,I21/I8,0) -> 3.1289762 | ... M22: =IF(M8>0,M21/M8,0) -> 1.4510458
A23: Contribution margin per user | B23: =B20-B22 -> -8.177135 | C23: =C20-C22 -> -1.4683683 | D23: =D20-D22 -> 3.413145 | E23: =E20-E22 -> 7.3200181 | F23: =F20-F22 -> 6.1244725 | G23: =G20-G22 -> 8.3868757 | H23: =H20-H22 -> 8.5694591 | I23: =I20-I22 -> 9.6120162 | ... M23: =M20-M22 -> 11.464062
A24: Monthly burn (Cost - Net Rev) | B24: =B21-B17 -> 16.35427 | C24: =C21-C17 -> 4.405105 | D24: =D21-D17 -> -17.065725 | E24: =E21-E17 -> -58.560145 | F24: =F21-F17 -> -61.244725 | G24: =G21-G17 -> -117.41626 | H24: =H21-H17 -> -145.6808 | I24: =I21-I17 -> -201.85234 | ... M24: =M21-M17 -> -550.27497
